Workbook

Sheet Tổng quan
A1: Tổng quan lỗi
A2: Tự cập nhật theo sheet “Danh sách lỗi”. Không nhập vào sheet này.
A4: Chỉ số | B4: Giá trị
A5: Tổng số lỗi | B5: =COUNTA('Danh sách lỗi'!$A$2:$A$301)
A6: Đang mở | B6: =B5-B7
A7: Đã đóng | B7: =COUNTIF('Danh sách lỗi'!$N$2:$N$301,"Đã sửa")+COUNTIF('Danh sách lỗi'!$N$2:$N$301,"Không tái hiện được")+COUNTIF('Danh sách lỗi'!$N$2:$N$301,"Không sửa")+COUNTIF('Danh sách lỗi'!$N$2:$N$301,"Trùng lặp")
A8: Đang mở – Nghiêm trọng hoặc Cao | B8: =COUNTIF('Danh sách lỗi'!$G$2:$G$301,"Nghiêm trọng")+COUNTIF('Danh sách lỗi'!$G$2:$G$301,"Cao")-SUMPRODUCT((('Danh sách lỗi'!$G$2:$G$301="Nghiêm trọng")+('Danh sách lỗi'!$G$2:$G$301="Cao"))*ISNUMBER(MATCH('Danh sách lỗi'!$N$2:$N$301,$A$46:$A$49,0)))
A9: Số ngày mở trung bình (lỗi chưa có ngày đóng) | B9: =IFERROR(AVERAGEIFS('Danh sách lỗi'!$Q$2:$Q$301,'Danh sách lỗi'!$B$2:$B$301,"<>",'Danh sách lỗi'!$P$2:$P$301,""),0)
A11: Trạng thái | B11: Số lỗi
A12: Mới | B12: =COUNTIF('Danh sách lỗi'!$N$2:$N$301,A12)
A13: Đã xác nhận | B13: =COUNTIF('Danh sách lỗi'!$N$2:$N$301,A13)
A14: Đang xử lý | B14: =COUNTIF('Danh sách lỗi'!$N$2:$N$301,A14)
A15: Chờ kiểm tra | B15: =COUNTIF('Danh sách lỗi'!$N$2:$N$301,A15)
A16: Đã sửa | B16: =COUNTIF('Danh sách lỗi'!$N$2:$N$301,A16)
A17: Không tái hiện được | B17: =COUNTIF('Danh sách lỗi'!$N$2:$N$301,A17)
A18: Không sửa | B18: =COUNTIF('Danh sách lỗi'!$N$2:$N$301,A18)
A19: Trùng lặp | B19: =COUNTIF('Danh sách lỗi'!$N$2:$N$301,A19)
A21: Mức độ | B21: Tổng | C21: Đang mở
A22: Nghiêm trọng | B22: =COUNTIF('Danh sách lỗi'!$G$2:$G$301,A22) | C22: =B22-SUMPRODUCT(('Danh sách lỗi'!$G$2:$G$301=A22)*ISNUMBER(MATCH('Danh sách lỗi'!$N$2:$N$301,$A$46:$A$49,0)))
A23: Cao | B23: =COUNTIF('Danh sách lỗi'!$G$2:$G$301,A23) | C23: =B23-SUMPRODUCT(('Danh sách lỗi'!$G$2:$G$301=A23)*ISNUMBER(MATCH('Danh sách lỗi'!$N$2:$N$301,$A$46:$A$49,0)))
A24: Trung bình | B24: =COUNTIF('Danh sách lỗi'!$G$2:$G$301,A24) | C24: =B24-SUMPRODUCT(('Danh sách lỗi'!$G$2:$G$301=A24)*ISNUMBER(MATCH('Danh sách lỗi'!$N$2:$N$301,$A$46:$A$49,0)))
A25: Thấp | B25: =COUNTIF('Danh sách lỗi'!$G$2:$G$301,A25) | C25: =B25-SUMPRODUCT(('Danh sách lỗi'!$G$2:$G$301=A25)*ISNUMBER(MATCH('Danh sách lỗi'!$N$2:$N$301,$A$46:$A$49,0)))
A27: Phần bị ảnh hưởng | B27: Tổng | C27: Đang mở
A28: Cài đặt skill | B28: =COUNTIF('Danh sách lỗi'!$E$2:$E$301,A28) | C28: =B28-SUMPRODUCT(('Danh sách lỗi'!$E$2:$E$301=A28)*ISNUMBER(MATCH('Danh sách lỗi'!$N$2:$N$301,$A$46:$A$49,0)))
A29: SKILL.md / cách gọi skill | B29: =COUNTIF('Danh sách lỗi'!$E$2:$E$301,A29) | C29: =B29-SUMPRODUCT(('Danh sách lỗi'!$E$2:$E$301=A29)*ISNUMBER(MATCH('Danh sách lỗi'!$N$2:$N$301,$A$46:$A$49,0)))
A30: references/ | B30: =COUNTIF('Danh sách lỗi'!$E$2:$E$301,A30) | C30: =B30-SUMPRODUCT(('Danh sách lỗi'!$E$2:$E$301=A30)*ISNUMBER(MATCH('Danh sách lỗi'!$N$2:$N$301,$A$46:$A$49,0)))
A31: assets/project/ | B31: =COUNTIF('Danh sách lỗi'!$E$2:$E$301,A31) | C31: =B31-SUMPRODUCT(('Danh sách lỗi'!$E$2:$E$301=A31)*ISNUMBER(MATCH('Danh sách lỗi'!$N$2:$N$301,$A$46:$A$49,0)))
A32: Design token | B32: =COUNTIF('Danh sách lỗi'!$E$2:$E$301,A32) | C32: =B32-SUMPRODUCT(('Danh sách lỗi'!$E$2:$E$301=A32)*ISNUMBER(MATCH('Danh sách lỗi'!$N$2:$N$301,$A$46:$A$49,0)))
A33: new_project.py | B33: =COUNTIF('Danh sách lỗi'!$E$2:$E$301,A33) | C33: =B33-SUMPRODUCT(('Danh sách lỗi'!$E$2:$E$301=A33)*ISNUMBER(MATCH('Danh sách lỗi'!$N$2:$N$301,$A$46:$A$49,0)))
A34: check_tokens.py | B34: =COUNTIF('Danh sách lỗi'!$E$2:$E$301,A34) | C34: =B34-SUMPRODUCT(('Danh sách lỗi'!$E$2:$E$301=A34)*ISNUMBER(MATCH('Danh sách lỗi'!$N$2:$N$301,$A$46:$A$49,0)))
A35: Figma MCP | B35: =COUNTIF('Danh sách lỗi'!$E$2:$E$301,A35) | C35: =B35-SUMPRODUCT(('Danh sách lỗi'!$E$2:$E$301=A35)*ISNUMBER(MATCH('Danh sách lỗi'!$N$2:$N$301,$A$46:$A$49,0)))
A36: Tavily | B36: =COUNTIF('Danh sách lỗi'!$E$2:$E$301,A36) | C36: =B36-SUMPRODUCT(('Danh sách lỗi'!$E$2:$E$301=A36)*ISNUMBER(MATCH('Danh sách lỗi'!$N$2:$N$301,$A$46:$A$49,0)))
A37: Antigravity | B37: =COUNTIF('Danh sách lỗi'!$E$2:$E$301,A37) | C37: =B37-SUMPRODUCT(('Danh sách lỗi'!$E$2:$E$301=A37)*ISNUMBER(MATCH('Danh sách lỗi'!$N$2:$N$301,$A$46:$A$49,0)))
A38: Style Văn Minh Việt | B38: =COUNTIF('Danh sách lỗi'!$E$2:$E$301,A38) | C38: =B38-SUMPRODUCT(('Danh sách lỗi'!$E$2:$E$301=A38)*ISNUMBER(MATCH('Danh sách lỗi'!$N$2:$N$301,$A$46:$A$49,0)))
A39: README / tài liệu | B39: =COUNTIF('Danh sách lỗi'!$E$2:$E$301,A39) | C39: =B39-SUMPRODUCT(('Danh sách lỗi'!$E$2:$E$301=A39)*ISNUMBER(MATCH('Danh sách lỗi'!$N$2:$N$301,$A$46:$A$49,0)))
A40: Khác | B40: =COUNTIF('Danh sách lỗi'!$E$2:$E$301,A40) | C40: =B40-SUMPRODUCT(('Danh sách lỗi'!$E$2:$E$301=A40)*ISNUMBER(MATCH('Danh sách lỗi'!$N$2:$N$301,$A$46:$A$49,0)))
A45: Trạng thái được tính là đã đóng (dùng cho công thức)
A46: Đã sửa
A47: Không tái hiện được
A48: Không sửa
...

Sheet Hướng dẫn
A1: Bảng theo dõi lỗi – UI/UX Workflow Skills
A3: Cách dùng
A4: 1. | B4: Mỗi lỗi ghi một dòng trong sheet “Danh sách lỗi”, bắt đầu từ dòng 3 (dòng 2 là ví dụ, có thể xoá).
A5: 2. | B5: Chỉ nhập vào các ô nền vàng nhạt. Cột “Số ngày mở” tự tính, đừng gõ đè.
A6: 3. | B6: Các cột Phần bị ảnh hưởng, Môi trường, Mức độ, Ưu tiên, Trạng thái chọn từ danh sách thả xuống.
A7: 4. | B7: Ngày nhập theo dạng dd/mm/yyyy. Mã lỗi theo dạng BUG-001, BUG-002…
A8: 5. | B8: Không dán API key, token Figma/Tavily, mật khẩu hay dữ liệu người dùng thật.
A9: 6. | B9: Nếu lỗi đã tạo issue trên GitHub, dán link vào cột “Link GitHub issue”.
A11: Mức độ
A12: Nghiêm trọng | B12: Không cài được skill, script hỏng hoàn toàn, hoặc làm lộ/mất dữ liệu.
A13: Cao | B13: Một bước chính của quy trình sai hoặc không chạy được, không có cách né.
A14: Trung bình | B14: Sai nhưng có cách né; kết quả lệch so với hướng dẫn.
A15: Thấp | B15: Lỗi chính tả, trình bày, tài liệu chưa rõ.
A17: Trạng thái đã đóng | B17: Đã sửa, Không tái hiện được, Không sửa, Trùng lặp. Các trạng thái khác được tính là đang mở.
A19: Ô nền vàng nhạt = ô cần nhập

Sheet Danh sách lỗi
A1: Mã lỗi | B1: Ngày báo | C1: Người báo | D1: Tiêu đề | E1: Phần bị ảnh hưởng | F1: Môi trường | G1: Mức độ | H1: Ưu tiên | I1: Các bước tái hiện | J1: Kết quả mong đợi | K1: Kết quả thực tế | L1: Commit / phiên bản | M1: Ảnh / log / link bằng chứng | N1: Trạng thái | O1: Người xử lý | P1: Ngày đóng | Q1: Số ngày mở | R1: Link GitHub issue | S1: Ghi chú
A2: BUG-001 | B2: 46318 | C2: nhandan28 | D2: new_project.py lỗi mã hoá khi tên dự án có dấu | E2: new_project.py | F2: Codex | G2: Cao | H2: P2 | I2: 1. Chạy: python scripts/new_project.py "Bảo tàng số" 2. Xem thư mục được tạo | J2: Tạo thư mục hồ sơ dự án với tên có dấu đúng | K2: Báo UnicodeEncodeError, không tạo thư mục | L2: 70d7fe1 | M2: Ảnh chụp terminal (link Drive) | N2: Đang xử lý | Q2: =IF(B2="","",IF(P2="",TODAY()-B2,P2-B2)) | S2: Chỉ gặp trên Windows PowerShell 5
Q3: =IF(B3="","",IF(P3="",TODAY()-B3,P3-B3))
Q4: =IF(B4="","",IF(P4="",TODAY()-B4,P4-B4))
Q5: =IF(B5="","",IF(P5="",TODAY()-B5,P5-B5))
Q6: =IF(B6="","",IF(P6="",TODAY()-B6,P6-B6))
Q7: =IF(B7="","",IF(P7="",TODAY()-B7,P7-B7))
Q8: =IF(B8="","",IF(P8="",TODAY()-B8,P8-B8))
Q9: =IF(B9="","",IF(P9="",TODAY()-B9,P9-B9))
Q10: =IF(B10="","",IF(P10="",TODAY()-B10,P10-B10))
Q11: =IF(B11="","",IF(P11="",TODAY()-B11,P11-B11))
Q12: =IF(B12="","",IF(P12="",TODAY()-B12,P12-B12))
Q13: =IF(B13="","",IF(P13="",TODAY()-B13,P13-B13))
Q14: =IF(B14="","",IF(P14="",TODAY()-B14,P14-B14))
... Q301: =IF(B301="","",IF(P301="",TODAY()-B301,P301-B301))
